OperationalError
sqlalchemy.exc.OperationalError: (psycopg2.OperationalError) connection to server at "ep-withered-river-a48boc9g.us-east-1.aws.neon.tech" (52.20.107.131), port 5432 failed: ERROR:  Console request failed: endpoint is disabled

(Background on this error at: https://sqlalche.me/e/20/e3q8)

Traceback (most recent call last)
File "/home/runner/AnaleeOriginal/.pythonlibs/lib/python3.11/site-packages/sqlalchemy/engine/base.py", line 146, in __init__
self._dbapi_connection = engine.raw_connection()
                         ^^^^^^^^^^^^^^^^^^^^^^^
File "/home/runner/AnaleeOriginal/.pythonlibs/lib/python3.11/site-packages/sqlalchemy/engine/base.py", line 3302, in raw_connection
return self.pool.connect()
       ^^^^^^^^^^^^^^^^^^^
File "/home/runner/AnaleeOriginal/.pythonlibs/lib/python3.11/site-packages/sqlalchemy/pool/base.py", line 449, in connect
return _ConnectionFairy._checkout(self)
       ^^^^^^^^^^^^^^^^^^^^^^^^^^^^^^^^
File "/home/runner/AnaleeOriginal/.pythonlibs/lib/python3.11/site-packages/sqlalchemy/pool/base.py", line 1263, in _checkout
fairy = _ConnectionRecord.checkout(pool)
        ^^^^^^^^^^^^^^^^^^^^^^^^^^^^^^^^
File "/home/runner/AnaleeOriginal/.pythonlibs/lib/python3.11/site-packages/sqlalchemy/pool/base.py", line 712, in checkout
rec = pool._do_get()
      ^^^^^^^^^^^^^^
File "/home/runner/AnaleeOriginal/.pythonlibs/lib/python3.11/site-packages/sqlalchemy/pool/impl.py", line 179, in _do_get
with util.safe_reraise():
^^^^^^^^^^^^^^^^^^^^^^^^
File "/home/runner/AnaleeOriginal/.pythonlibs/lib/python3.11/site-packages/sqlalchemy/util/langhelpers.py", line 146, in __exit__
raise exc_value.with_traceback(exc_tb)
^^^^^^^^^^^^^^^^^^^^^^^^^^^^^^^^^^^^^^
File "/home/runner/AnaleeOriginal/.pythonlibs/lib/python3.11/site-packages/sqlalchemy/pool/impl.py", line 177, in _do_get
return self._create_connection()
       ^^^^^^^^^^^^^^^^^^^^^^^^^
File "/home/runner/AnaleeOriginal/.pythonlibs/lib/python3.11/site-packages/sqlalchemy/pool/base.py", line 390, in _create_connection
return _ConnectionRecord(self)
       ^^^^^^^^^^^^^^^^^^^^^^^
File "/home/runner/AnaleeOriginal/.pythonlibs/lib/python3.11/site-packages/sqlalchemy/pool/base.py", line 674, in __init__
self.__connect()
^^^^^^^^^^^^^^^^
File "/home/runner/AnaleeOriginal/.pythonlibs/lib/python3.11/site-packages/sqlalchemy/pool/base.py", line 900, in __connect
with util.safe_reraise():
^^^^^^^^^^^^^^^^^^^^^^^^^^^^^^^^^^^^^^^^^^^^^^^^^^
File "/home/runner/AnaleeOriginal/.pythonlibs/lib/python3.11/site-packages/sqlalchemy/util/langhelpers.py", line 146, in __exit__
raise exc_value.with_traceback(exc_tb)
^^^^^^^^^^^^^^^^^^^^^^^^^^^^^^^^^^^^^^
File "/home/runner/AnaleeOriginal/.pythonlibs/lib/python3.11/site-packages/sqlalchemy/pool/base.py", line 896, in __connect
self.dbapi_connection = connection = pool._invoke_creator(self)
                                     ^^^^^^^^^^^^^^^^^^^^^^^^^^
File "/home/runner/AnaleeOriginal/.pythonlibs/lib/python3.11/site-packages/sqlalchemy/engine/create.py", line 643, in connect
return dialect.connect(*cargs, **cparams)
       ^^^^^^^^^^^^^^^^^^^^^^^^^^^^^^^^^^
File "/home/runner/AnaleeOriginal/.pythonlibs/lib/python3.11/site-packages/sqlalchemy/engine/default.py", line 621, in connect
return self.loaded_dbapi.connect(*cargs, **cparams)
       ^^^^^^^^^^^^^^^^^^^^^^^^^^^^^^^^^^^^^^^^^^^^
File "/home/runner/AnaleeOriginal/.pythonlibs/lib/python3.11/site-packages/psycopg2/__init__.py", line 122, in connect
conn = _connect(dsn, connection_factory=connection_factory, **kwasync)
       ^^^^^^^^^^^^^^^^^^^^^^^^^^^^^^^^^^^^^^^^^^^^^^^^^^^^^^^^^^^^^^^
The above exception was the direct cause of the following exception:
File "/home/runner/AnaleeOriginal/.pythonlibs/lib/python3.11/site-packages/flask/app.py", line 1536, in __call__
return self.wsgi_app(environ, start_response)
       ^^^^^^^^^^^^^^^^^^^^^^^^^^^^^^^^^^^^^^
File "/home/runner/AnaleeOriginal/.pythonlibs/lib/python3.11/site-packages/flask/app.py", line 1514, in wsgi_app
response = self.handle_exception(e)
           ^^^^^^^^^^^^^^^^^^^^^^^^
File "/home/runner/AnaleeOriginal/.pythonlibs/lib/python3.11/site-packages/flask/app.py", line 1511, in wsgi_app
response = self.full_dispatch_request()
           ^^^^^^^^^^^^^^^^^^^^^^^^^^^^
File "/home/runner/AnaleeOriginal/.pythonlibs/lib/python3.11/site-packages/flask/app.py", line 919, in full_dispatch_request
rv = self.handle_user_exception(e)
     ^^^^^^^^^^^^^^^^^^^^^^^^^^^^^
File "/home/runner/AnaleeOriginal/.pythonlibs/lib/python3.11/site-packages/flask/app.py", line 917, in full_dispatch_request
rv = self.dispatch_request()
     ^^^^^^^^^^^^^^^^^^^^^^^
File "/home/runner/AnaleeOriginal/.pythonlibs/lib/python3.11/site-packages/flask/app.py", line 902, in dispatch_request
return self.ensure_sync(self.view_functions[rule.endpoint])(**view_args)  # type: ignore[no-any-return]
       ^^^^^^^^^^^^^^^^^^^^^^^^^^^^^^^^^^^^^^^^^^^^^^^^^^^^^^^^^^^^^^^^^
File "/home/runner/AnaleeOriginal/auth/routes.py", line 28, in login
user = User.query.filter_by(email=email).first()
       ^^^^^^^^^^^^^^^^^^^^^^^^^^^^^^^^^^^^^^^^^
File "/home/runner/AnaleeOriginal/.pythonlibs/lib/python3.11/site-packages/sqlalchemy/orm/query.py", line 2728, in first
return self.limit(1)._iter().first()  # type: ignore
       ^^^^^^^^^^^^^^^^^^^^^
File "/home/runner/AnaleeOriginal/.pythonlibs/lib/python3.11/site-packages/sqlalchemy/orm/query.py", line 2827, in _iter
result: Union[ScalarResult[_T], Result[_T]] = self.session.execute(
                                              
File "/home/runner/AnaleeOriginal/.pythonlibs/lib/python3.11/site-packages/sqlalchemy/orm/session.py", line 2362, in execute
return self._execute_internal(
       
File "/home/runner/AnaleeOriginal/.pythonlibs/lib/python3.11/site-packages/sqlalchemy/orm/session.py", line 2237, in _execute_internal
conn = self._connection_for_bind(bind)
       ^^^^^^^^^^^^^^^^^^^^^^^^^^^^^^^
File "/home/runner/AnaleeOriginal/.pythonlibs/lib/python3.11/site-packages/sqlalchemy/orm/session.py", line 2106, in _connection_for_bind
return trans._connection_for_bind(engine, execution_options)
       ^^^^^^^^^^^^^^^^^^^^^^^^^^^^^^^^^^^^^^^^^^^^^^^^^^^^^
File "<string>", line 2, in _connection_for_bind
File "/home/runner/AnaleeOriginal/.pythonlibs/lib/python3.11/site-packages/sqlalchemy/orm/state_changes.py", line 139, in _go
ret_value = fn(self, *arg, **kw)
            ^^^^^^^^^^^^^^^^^^^^
File "/home/runner/AnaleeOriginal/.pythonlibs/lib/python3.11/site-packages/sqlalchemy/orm/session.py", line 1189, in _connection_for_bind
conn = bind.connect()
       ^^^^^^^^^^^^^^
File "/home/runner/AnaleeOriginal/.pythonlibs/lib/python3.11/site-packages/sqlalchemy/engine/base.py", line 3278, in connect
return self._connection_cls(self)
       ^^^^^^^^^^^^^^^^^^^^^^^^^^
File "/home/runner/AnaleeOriginal/.pythonlibs/lib/python3.11/site-packages/sqlalchemy/engine/base.py", line 148, in __init__
Connection._handle_dbapi_exception_noconnection(
^
File "/home/runner/AnaleeOriginal/.pythonlibs/lib/python3.11/site-packages/sqlalchemy/engine/base.py", line 2442, in _handle_dbapi_exception_noconnection
raise sqlalchemy_exception.with_traceback(exc_info[2]) from e
^^^^^^^^^^^^^^^^^^^^^^^^^^^^^^^^^^^^^^^^^^^^^^^^^^^^^^^^^^^^^
File "/home/runner/AnaleeOriginal/.pythonlibs/lib/python3.11/site-packages/sqlalchemy/engine/base.py", line 146, in __init__
self._dbapi_connection = engine.raw_connection()
                         ^^^^^^^^^^^^^^^^^^^^^^^
File "/home/runner/AnaleeOriginal/.pythonlibs/lib/python3.11/site-packages/sqlalchemy/engine/base.py", line 3302, in raw_connection
return self.pool.connect()
       ^^^^^^^^^^^^^^^^^^^
File "/home/runner/AnaleeOriginal/.pythonlibs/lib/python3.11/site-packages/sqlalchemy/pool/base.py", line 449, in connect
return _ConnectionFairy._checkout(self)
       ^^^^^^^^^^^^^^^^^^^^^^^^^^^^^^^^
File "/home/runner/AnaleeOriginal/.pythonlibs/lib/python3.11/site-packages/sqlalchemy/pool/base.py", line 1263, in _checkout
fairy = _ConnectionRecord.checkout(pool)
        ^^^^^^^^^^^^^^^^^^^^^^^^^^^^^^^^
File "/home/runner/AnaleeOriginal/.pythonlibs/lib/python3.11/site-packages/sqlalchemy/pool/base.py", line 712, in checkout
rec = pool._do_get()
      ^^^^^^^^^^^^^^
File "/home/runner/AnaleeOriginal/.pythonlibs/lib/python3.11/site-packages/sqlalchemy/pool/impl.py", line 179, in _do_get
with util.safe_reraise():
^^^^^^^^^^^^^^^^^^^^^^^^
File "/home/runner/AnaleeOriginal/.pythonlibs/lib/python3.11/site-packages/sqlalchemy/util/langhelpers.py", line 146, in __exit__
raise exc_value.with_traceback(exc_tb)
^^^^^^^^^^^^^^^^^^^^^^^^^^^^^^^^^^^^^^
File "/home/runner/AnaleeOriginal/.pythonlibs/lib/python3.11/site-packages/sqlalchemy/pool/impl.py", line 177, in _do_get
return self._create_connection()
       ^^^^^^^^^^^^^^^^^^^^^^^^^
File "/home/runner/AnaleeOriginal/.pythonlibs/lib/python3.11/site-packages/sqlalchemy/pool/base.py", line 390, in _create_connection
return _ConnectionRecord(self)
       ^^^^^^^^^^^^^^^^^^^^^^^
File "/home/runner/AnaleeOriginal/.pythonlibs/lib/python3.11/site-packages/sqlalchemy/pool/base.py", line 674, in __init__
self.__connect()
^^^^^^^^^^^^^^^^
File "/home/runner/AnaleeOriginal/.pythonlibs/lib/python3.11/site-packages/sqlalchemy/pool/base.py", line 900, in __connect
with util.safe_reraise():
^^^^^^^^^^^^^^^^^^^^^^^^^^^^^^^^^^^^^^^^^^^^^^^^^^
File "/home/runner/AnaleeOriginal/.pythonlibs/lib/python3.11/site-packages/sqlalchemy/util/langhelpers.py", line 146, in __exit__
raise exc_value.with_traceback(exc_tb)
^^^^^^^^^^^^^^^^^^^^^^^^^^^^^^^^^^^^^^
File "/home/runner/AnaleeOriginal/.pythonlibs/lib/python3.11/site-packages/sqlalchemy/pool/base.py", line 896, in __connect
self.dbapi_connection = connection = pool._invoke_creator(self)
                                     ^^^^^^^^^^^^^^^^^^^^^^^^^^
File "/home/runner/AnaleeOriginal/.pythonlibs/lib/python3.11/site-packages/sqlalchemy/engine/create.py", line 643, in connect
return dialect.connect(*cargs, **cparams)
       ^^^^^^^^^^^^^^^^^^^^^^^^^^^^^^^^^^
File "/home/runner/AnaleeOriginal/.pythonlibs/lib/python3.11/site-packages/sqlalchemy/engine/default.py", line 621, in connect
return self.loaded_dbapi.connect(*cargs, **cparams)
       ^^^^^^^^^^^^^^^^^^^^^^^^^^^^^^^^^^^^^^^^^^^^
File "/home/runner/AnaleeOriginal/.pythonlibs/lib/python3.11/site-packages/psycopg2/__init__.py", line 122, in connect
conn = _connect(dsn, connection_factory=connection_factory, **kwasync)
       ^^^^^^^^^^^^^^^^^^^^^^^^^^^^^^^^^^^^^^^^^^^^^^^^^^^^^^^^^^^^^^^
sqlalchemy.exc.OperationalError: (psycopg2.OperationalError) connection to server at "ep-withered-river-a48boc9g.us-east-1.aws.neon.tech" (52.20.107.131), port 5432 failed: ERROR: Console request failed: endpoint is disabled

(Background on this error at: https://sqlalche.me/e/20/e3q8)
The debugger caught an exception in your WSGI application. You can now look at the traceback which led to the error.
To switch between the interactive traceback and the plaintext one, you can click on the "Traceback" headline. From the text traceback you can also create a paste of it.

Brought to you by DON'T PANIC, your friendly Werkzeug powered traceback interpreter.